Workbook

Sheet Instructions
A1: County Target Industry Template
A2: Statewide Pathway Explorer — target industries for all 159 Georgia counties
A4: What this is for
A5: One row per county, all 159 pre-loaded. For each county, record up to three target industries in priority order, plus where that information came from. This drives which programs appear on each county page, so the source column matters as much as the answer.
A7: Start here
A8: Fill the four showcase counties first -- Forsyth, Jackson, Houston, Ware -- then work outward by region. Those four already have draft values you should verify with the EDA directly.
A10: Where to look, in order of preference
A11: 1. The county or regional target industry study (most authoritative -- ask the EDA for the PDF).
A12: 2. The EDA's own website, usually an 'Industries' or 'Target Sectors' page.
A13: 3. The Regional Commission's comprehensive economic development strategy (CEDS).
A14: 4. Georgia Department of Economic Development regional materials.
A15: 5. Existing major employers, as a last resort -- mark Confidence as Low if this is all you have.
... A26: The four showcase rows are marked DRAFT and are starting points for your EDA conversations, not verified facts. Replace the source with the real document once you have it, then change Confidence to High.

Sheet Counties
A1: County | B1: Slug | C1: FIPS | D1: County seat | E1: Region | F1: EDA / organization | G1: Target industry 1 | H1: Sub-sector 1 | I1: Target industry 2 | J1: Sub-sector 2 | K1: Target industry 3 | L1: Sub-sector 3 | M1: Source document | N1: Source URL | O1: Source year | P1: Confidence | Q1: EDA contact name | R1: EDA contact email | S1: Researched by | T1: Researched date | U1: Notes | V1: QC check
A2: Appling | B2: =LOWER(SUBSTITUTE(A2," ","-")) | V2: =IF(ISBLANK(G2),"Not started",IF(ISBLANK(M2),"Missing source",IF(LEFT(M2,5)="DRAFT","Draft - verify with EDA",IF(ISBLANK(P2),"Missing confidence",IF(ISBLANK(H2),"Missing sub-sector","OK")))))
A3: Atkinson | B3: =LOWER(SUBSTITUTE(A3," ","-")) | V3: =IF(ISBLANK(G3),"Not started",IF(ISBLANK(M3),"Missing source",IF(LEFT(M3,5)="DRAFT","Draft - verify with EDA",IF(ISBLANK(P3),"Missing confidence",IF(ISBLANK(H3),"Missing sub-sector","OK")))))
A4: Bacon | B4: =LOWER(SUBSTITUTE(A4," ","-")) | V4: =IF(ISBLANK(G4),"Not started",IF(ISBLANK(M4),"Missing source",IF(LEFT(M4,5)="DRAFT","Draft - verify with EDA",IF(ISBLANK(P4),"Missing confidence",IF(ISBLANK(H4),"Missing sub-sector","OK")))))
A5: Baker | B5: =LOWER(SUBSTITUTE(A5," ","-")) | V5: =IF(ISBLANK(G5),"Not started",IF(ISBLANK(M5),"Missing source",IF(LEFT(M5,5)="DRAFT","Draft - verify with EDA",IF(ISBLANK(P5),"Missing confidence",IF(ISBLANK(H5),"Missing sub-sector","OK")))))
A6: Baldwin | B6: =LOWER(SUBSTITUTE(A6," ","-")) | V6: =IF(ISBLANK(G6),"Not started",IF(ISBLANK(M6),"Missing source",IF(LEFT(M6,5)="DRAFT","Draft - verify with EDA",IF(ISBLANK(P6),"Missing confidence",IF(ISBLANK(H6),"Missing sub-sector","OK")))))
A7: Banks | B7: =LOWER(SUBSTITUTE(A7," ","-")) | V7: =IF(ISBLANK(G7),"Not started",IF(ISBLANK(M7),"Missing source",IF(LEFT(M7,5)="DRAFT","Draft - verify with EDA",IF(ISBLANK(P7),"Missing confidence",IF(ISBLANK(H7),"Missing sub-sector","OK")))))
A8: Barrow | B8: =LOWER(SUBSTITUTE(A8," ","-")) | V8: =IF(ISBLANK(G8),"Not started",IF(ISBLANK(M8),"Missing source",IF(LEFT(M8,5)="DRAFT","Draft - verify with EDA",IF(ISBLANK(P8),"Missing confidence",IF(ISBLANK(H8),"Missing sub-sector","OK")))))
A9: Bartow | B9: =LOWER(SUBSTITUTE(A9," ","-")) | V9: =IF(ISBLANK(G9),"Not started",IF(ISBLANK(M9),"Missing source",IF(LEFT(M9,5)="DRAFT","Draft - verify with EDA",IF(ISBLANK(P9),"Missing confidence",IF(ISBLANK(H9),"Missing sub-sector","OK")))))
A10: Ben Hill | B10: =LOWER(SUBSTITUTE(A10," ","-")) | V10: =IF(ISBLANK(G10),"Not started",IF(ISBLANK(M10),"Missing source",IF(LEFT(M10,5)="DRAFT","Draft - verify with EDA",IF(ISBLANK(P10),"Missing confidence",IF(ISBLANK(H10),"Missing sub-sector","OK")))))
A11: Berrien | B11: =LOWER(SUBSTITUTE(A11," ","-")) | V11: =IF(ISBLANK(G11),"Not started",IF(ISBLANK(M11),"Missing source",IF(LEFT(M11,5)="DRAFT","Draft - verify with EDA",IF(ISBLANK(P11),"Missing confidence",IF(ISBLANK(H11),"Missing sub-sector","OK")))))
A12: Bibb | B12: =LOWER(SUBSTITUTE(A12," ","-")) | V12: =IF(ISBLANK(G12),"Not started",IF(ISBLANK(M12),"Missing source",IF(LEFT(M12,5)="DRAFT","Draft - verify with EDA",IF(ISBLANK(P12),"Missing confidence",IF(ISBLANK(H12),"Missing sub-sector","OK")))))
A13: Bleckley | B13: =LOWER(SUBSTITUTE(A13," ","-")) | V13: =IF(ISBLANK(G13),"Not started",IF(ISBLANK(M13),"Missing source",IF(LEFT(M13,5)="DRAFT","Draft - verify with EDA",IF(ISBLANK(P13),"Missing confidence",IF(ISBLANK(H13),"Missing sub-sector","OK")))))
... A58: Floyd | B58: =LOWER(SUBSTITUTE(A58," ","-")) | V58: =IF(ISBLANK(G58),"Not started",IF(ISBLANK(M58),"Missing source",IF(LEFT(M58,5)="DRAFT","Draft - verify with EDA",IF(ISBLANK(P58),"Missing confidence",IF(ISBLANK(H58),"Missing sub-sector","OK")))))
A59: Forsyth | B59: =LOWER(SUBSTITUTE(A59," ","-")) | D59: Cumming | E59: 3 - Atlanta Regional | F59: Cumming-Forsyth County Chamber of Commerce | G59: Technology & IT | H59: Software Development | I59: Professional Services & HQ | J59: Corporate Headquarters | K59: Healthcare | L59: Hospitals & Health Systems | M59: DRAFT - to be confirmed with EDA | P59: Low | U59: DRAFT - verify with EDA. Lanier Tech Forsyth Campus in Cumming. | V59: =IF(ISBLANK(G59),"Not started",IF(ISBLANK(M59),"Missing source",IF(LEFT(M59,5)="DRAFT","Draft - verify with EDA",IF(ISBLANK(P59),"Missing confidence",IF(ISBLANK(H59),"Missing sub-sector","OK")))))
A60: Franklin | B60: =LOWER(SUBSTITUTE(A60," ","-")) | V60: =IF(ISBLANK(G60),"Not started",IF(ISBLANK(M60),"Missing source",IF(LEFT(M60,5)="DRAFT","Draft - verify with EDA",IF(ISBLANK(P60),"Missing confidence",IF(ISBLANK(H60),"Missing sub-sector","OK")))))
A61: Fulton | B61: =LOWER(SUBSTITUTE(A61," ","-")) | V61: =IF(ISBLANK(G61),"Not started",IF(ISBLANK(M61),"Missing source",IF(LEFT(M61,5)="DRAFT","Draft - verify with EDA",IF(ISBLANK(P61),"Missing confidence",IF(ISBLANK(H61),"Missing sub-sector","OK")))))
A62: Gilmer | B62: =LOWER(SUBSTITUTE(A62," ","-")) | V62: =IF(ISBLANK(G62),"Not started",IF(ISBLANK(M62),"Missing source",IF(LEFT(M62,5)="DRAFT","Draft - verify with EDA",IF(ISBLANK(P62),"Missing confidence",IF(ISBLANK(H62),"Missing sub-sector","OK")))))
A63: Glascock | B63: =LOWER(SUBSTITUTE(A63," ","-")) | V63: =IF(ISBLANK(G63),"Not started",IF(ISBLANK(M63),"Missing source",IF(LEFT(M63,5)="DRAFT","Draft - verify with EDA",IF(ISBLANK(P63),"Missing confidence",IF(ISBLANK(H63),"Missing sub-sector","OK")))))
A64: Glynn | B64: =LOWER(SUBSTITUTE(A64," ","-")) | V64: =IF(ISBLANK(G64),"Not started",IF(ISBLANK(M64),"Missing source",IF(LEFT(M64,5)="DRAFT","Draft - verify with EDA",IF(ISBLANK(P64),"Missing confidence",IF(ISBLANK(H64),"Missing sub-sector","OK")))))
A65: Gordon | B65: =LOWER(SUBSTITUTE(A65," ","-")) | V65: =IF(ISBLANK(G65),"Not started",IF(ISBLANK(M65),"Missing source",IF(LEFT(M65,5)="DRAFT","Draft - verify with EDA",IF(ISBLANK(P65),"Missing confidence",IF(ISBLANK(H65),"Missing sub-sector","OK")))))
A66: Grady | B66: =LOWER(SUBSTITUTE(A66," ","-")) | V66: =IF(ISBLANK(G66),"Not started",IF(ISBLANK(M66),"Missing source",IF(LEFT(M66,5)="DRAFT","Draft - verify with EDA",IF(ISBLANK(P66),"Missing confidence",IF(ISBLANK(H66),"Missing sub-sector","OK")))))
A67: Greene | B67: =LOWER(SUBSTITUTE(A67," ","-")) | V67: =IF(ISBLANK(G67),"Not started",IF(ISBLANK(M67),"Missing source",IF(LEFT(M67,5)="DRAFT","Draft - verify with EDA",IF(ISBLANK(P67),"Missing confidence",IF(ISBLANK(H67),"Missing sub-sector","OK")))))
A68: Gwinnett | B68: =LOWER(SUBSTITUTE(A68," ","-")) | V68: =IF(ISBLANK(G68),"Not started",IF(ISBLANK(M68),"Missing source",IF(LEFT(M68,5)="DRAFT","Draft - verify with EDA",IF(ISBLANK(P68),"Missing confidence",IF(ISBLANK(H68),"Missing sub-sector","OK")))))
A69: Habersham | B69: =LOWER(SUBSTITUTE(A69," ","-")) | V69: =IF(ISBLANK(G69),"Not started",IF(ISBLANK(M69),"Missing source",IF(LEFT(M69,5)="DRAFT","Draft - verify with EDA",IF(ISBLANK(P69),"Missing confidence",IF(ISBLANK(H69),"Missing sub-sector","OK")))))
A70: Hall | B70: =LOWER(SUBSTITUTE(A70," ","-")) | V70: =IF(ISBLANK(G70),"Not started",IF(ISBLANK(M70),"Missing source",IF(LEFT(M70,5)="DRAFT","Draft - verify with EDA",IF(ISBLANK(P70),"Missing confidence",IF(ISBLANK(H70),"Missing sub-sector","OK")))))
A71: Hancock | B71: =LOWER(SUBSTITUTE(A71," ","-")) | V71: =IF(ISBLANK(G71),"Not started",IF(ISBLANK(M71),"Missing source",IF(LEFT(M71,5)="DRAFT","Draft - verify with EDA",IF(ISBLANK(P71),"Missing confidence",IF(ISBLANK(H71),"Missing sub-sector","OK")))))
... A76: Henry | B76: =LOWER(SUBSTITUTE(A76," ","-")) | V76: =IF(ISBLANK(G76),"Not started",IF(ISBLANK(M76),"Missing source",IF(LEFT(M76,5)="DRAFT","Draft - verify with EDA",IF(ISBLANK(P76),"Missing confidence",IF(ISBLANK(H76),"Missing sub-sector","OK")))))
A77: Houston | B77: =LOWER(SUBSTITUTE(A77," ","-")) | D77: Perry | E77: 6 - Middle Georgia | F77: Development Authority of Houston County | G77: Advanced Manufacturing | H77: Aerospace & Defense | I77: Technology & IT | J77: Cybersecurity | K77: Healthcare | L77: Hospitals & Health Systems | M77: DRAFT - to be confirmed with EDA | P77: Low | U77: DRAFT - verify with EDA. Robins AFB anchors the economy; CGTC and MGSU both in Warner Robins. | V77: =IF(ISBLANK(G77),"Not started",IF(ISBLANK(M77),"Missing source",IF(LEFT(M77,5)="DRAFT","Draft - verify with EDA",IF(ISBLANK(P77),"Missing confidence",IF(ISBLANK(H77),"Missing sub-sector","OK")))))
A78: Irwin | B78: =LOWER(SUBSTITUTE(A78," ","-")) | V78: =IF(ISBLANK(G78),"Not started",IF(ISBLANK(M78),"Missing source",IF(LEFT(M78,5)="DRAFT","Draft - verify with EDA",IF(ISBLANK(P78),"Missing confidence",IF(ISBLANK(H78),"Missing sub-sector","OK")))))
A79: Jackson | B79: =LOWER(SUBSTITUTE(A79," ","-")) | D79: Jefferson | E79: 2 - Georgia Mountains | F79: Jackson County Area Chamber of Commerce | G79: Advanced Manufacturing | H79: Automotive & EV | I79: Professional Services & HQ | J79: Logistics & Supply Chain Management | K79: Healthcare | L79: Hospitals & Health Systems | M79: DRAFT - to be confirmed with EDA | P79: Low | U79: DRAFT - verify with EDA. SK Battery America in Commerce; Quick Start + Lanier Tech trained ~2,600. | V79: =IF(ISBLANK(G79),"Not started",IF(ISBLANK(M79),"Missing source",IF(LEFT(M79,5)="DRAFT","Draft - verify with EDA",IF(ISBLANK(P79),"Missing confidence",IF(ISBLANK(H79),"Missing sub-sector","OK")))))
A80: Jasper | B80: =LOWER(SUBSTITUTE(A80," ","-")) | V80: =IF(ISBLANK(G80),"Not started",IF(ISBLANK(M80),"Missing source",IF(LEFT(M80,5)="DRAFT","Draft - verify with EDA",IF(ISBLANK(P80),"Missing confidence",IF(ISBLANK(H80),"Missing sub-sector","OK")))))
A81: Jeff Davis | B81: =LOWER(SUBSTITUTE(A81," ","-")) | V81: =IF(ISBLANK(G81),"Not started",IF(ISBLANK(M81),"Missing source",IF(LEFT(M81,5)="DRAFT","Draft - verify with EDA",IF(ISBLANK(P81),"Missing confidence",IF(ISBLANK(H81),"Missing sub-sector","OK")))))
A82: Jefferson | B82: =LOWER(SUBSTITUTE(A82," ","-")) | V82: =IF(ISBLANK(G82),"Not started",IF(ISBLANK(M82),"Missing source",IF(LEFT(M82,5)="DRAFT","Draft - verify with EDA",IF(ISBLANK(P82),"Missing confidence",IF(ISBLANK(H82),"Missing sub-sector","OK")))))
A83: Jenkins | B83: =LOWER(SUBSTITUTE(A83," ","-")) | V83: =IF(ISBLANK(G83),"Not started",IF(ISBLANK(M83),"Missing source",IF(LEFT(M83,5)="DRAFT","Draft - verify with EDA",IF(ISBLANK(P83),"Missing confidence",IF(ISBLANK(H83),"Missing sub-sector","OK")))))
A84: Johnson | B84: =LOWER(SUBSTITUTE(A84," ","-")) | V84: =IF(ISBLANK(G84),"Not started",IF(ISBLANK(M84),"Missing source",IF(LEFT(M84,5)="DRAFT","Draft - verify with EDA",IF(ISBLANK(P84),"Missing confidence",IF(ISBLANK(H84),"Missing sub-sector","OK")))))
A85: Jones | B85: =LOWER(SUBSTITUTE(A85," ","-")) | V85: =IF(ISBLANK(G85),"Not started",IF(ISBLANK(M85),"Missing source",IF(LEFT(M85,5)="DRAFT","Draft - verify with EDA",IF(ISBLANK(P85),"Missing confidence",IF(ISBLANK(H85),"Missing sub-sector","OK")))))
A86: Lamar | B86: =LOWER(SUBSTITUTE(A86," ","-")) | V86: =IF(ISBLANK(G86),"Not started",IF(ISBLANK(M86),"Missing source",IF(LEFT(M86,5)="DRAFT","Draft - verify with EDA",IF(ISBLANK(P86),"Missing confidence",IF(ISBLANK(H86),"Missing sub-sector","OK")))))
A87: Lanier | B87: =LOWER(SUBSTITUTE(A87," ","-")) | V87: =IF(ISBLANK(G87),"Not started",IF(ISBLANK(M87),"Missing source",IF(LEFT(M87,5)="DRAFT","Draft - verify with EDA",IF(ISBLANK(P87),"Missing confidence",IF(ISBLANK(H87),"Missing sub-sector","OK")))))
A88: Laurens | B88: =LOWER(SUBSTITUTE(A88," ","-")) | V88: =IF(ISBLANK(G88),"Not started",IF(ISBLANK(M88),"Missing source",IF(LEFT(M88,5)="DRAFT","Draft - verify with EDA",IF(ISBLANK(P88),"Missing confidence",IF(ISBLANK(H88),"Missing sub-sector","OK")))))
...

Sheet Progress
A1: Research progress
A2: All figures calculate from the Counties tab. Nothing here needs editing.
A4: Coverage
A5: Counties in Georgia | B5: 159
A6: Counties with a target set | B6: =$B$5-COUNTIF(Counties!$V$2:$V$160,"Not started")
A7: Counties fully complete | B7: =COUNTIF(Counties!$V$2:$V$160,"OK")
A8: Draft - needs EDA verification | B8: =COUNTIF(Counties!$V$2:$V$160,"Draft - verify with EDA")
A9: Not started | B9: =COUNTIF(Counties!$V$2:$V$160,"Not started")
A10: Missing a source | B10: =COUNTIF(Counties!$V$2:$V$160,"Missing source")
A11: High confidence | B11: =COUNTIF(Counties!$P$2:$P$160,"High")
A12: Low confidence - ask the EDA | B12: =COUNTIF(Counties!$P$2:$P$160,"Low")
A13: Percent complete | B13: =$B$7/$B$5
A15: Counties naming each industry as a target
A16: Industry | B16: As #1 | C16: Any rank
A17: Advanced Manufacturing | B17: =COUNTIF(Counties!$G$2:$G$160,$A17) | C17: =COUNTIF(Counties!$G$2:$G$160,$A17)+COUNTIF(Counties!$I$2:$I$160,$A17)+COUNTIF(Counties!$K$2:$K$160,$A17)
A18: Healthcare | B18: =COUNTIF(Counties!$G$2:$G$160,$A18) | C18: =COUNTIF(Counties!$G$2:$G$160,$A18)+COUNTIF(Counties!$I$2:$I$160,$A18)+COUNTIF(Counties!$K$2:$K$160,$A18)
A19: Bio & Life Sciences | B19: =COUNTIF(Counties!$G$2:$G$160,$A19) | C19: =COUNTIF(Counties!$G$2:$G$160,$A19)+COUNTIF(Counties!$I$2:$I$160,$A19)+COUNTIF(Counties!$K$2:$K$160,$A19)
A20: Professional Services & HQ | B20: =COUNTIF(Counties!$G$2:$G$160,$A20) | C20: =COUNTIF(Counties!$G$2:$G$160,$A20)+COUNTIF(Counties!$I$2:$I$160,$A20)+COUNTIF(Counties!$K$2:$K$160,$A20)
A21: Technology & IT | B21: =COUNTIF(Counties!$G$2:$G$160,$A21) | C21: =COUNTIF(Counties!$G$2:$G$160,$A21)+COUNTIF(Counties!$I$2:$I$160,$A21)+COUNTIF(Counties!$K$2:$K$160,$A21)
A23: By region
A24: 1 - Northwest Georgia | B24: =COUNTIF(Counties!$E$2:$E$160,$A24)
A25: 2 - Georgia Mountains | B25: =COUNTIF(Counties!$E$2:$E$160,$A25)
A26: 3 - Atlanta Regional | B26: =COUNTIF(Counties!$E$2:$E$160,$A26)
A27: 4 - Three Rivers | B27: =COUNTIF(Counties!$E$2:$E$160,$A27)
A28: 5 - Northeast Georgia | B28: =COUNTIF(Counties!$E$2:$E$160,$A28)
A29: 6 - Middle Georgia | B29: =COUNTIF(Counties!$E$2:$E$160,$A29)
A30: 7 - Central Savannah River | B30: =COUNTIF(Counties!$E$2:$E$160,$A30)
A31: 8 - River Valley | B31: =COUNTIF(Counties!$E$2:$E$160,$A31)
A32: 9 - Heart of Georgia Altamaha | B32: =COUNTIF(Counties!$E$2:$E$160,$A32)
A33: 10 - Southwest Georgia | B33: =COUNTIF(Counties!$E$2:$E$160,$A33)
A34: 11 - Southern Georgia | B34: =COUNTIF(Counties!$E$2:$E$160,$A34)
A35: 12 - Coastal Georgia | B35: =COUNTIF(Counties!$E$2:$E$160,$A35)

Sheet Reference
A1: Reference lists
A2: Dropdown sources. Add rows at the bottom of a list to extend it; do not reorder or delete columns.
A4: Industry | B4: Sub-sector | C4: Credential type | D4: Delivery mode | E4: Yes/No | F4: Status | G4: Confidence | H4: System | I4: Region | J4: Institution
A5: Advanced Manufacturing | B5: Automotive & EV | C5: Technical Certificate of Credit | D5: In person | E5: Yes | F5: Example | G5: High | H5: TCSG | I5: 1 - Northwest Georgia | J5: Albany Technical College
A6: Healthcare | B6: Aerospace & Defense | C6: Diploma | D6: Hybrid | E6: No | F6: Draft | G6: Medium | H6: USG | I6: 2 - Georgia Mountains | J6: Athens Technical College
A7: Bio & Life Sciences | B7: Food & Beverage Processing | C7: Associate | D7: Online | E7: Unknown | F7: Needs review | G7: Low | H7: Private | I7: 3 - Atlanta Regional | J7: Atlanta Technical College
A8: Professional Services & HQ | B8: Industrial Machinery | C8: Bachelor's | F8: Ready for import | H8: Other | I8: 4 - Three Rivers | J8: Augusta Technical College
A9: Technology & IT | B9: Textiles & Flooring | C9: Master's | I9: 5 - Northeast Georgia | J9: Central Georgia Technical College
B10: Forest Products & Packaging | C10: Apprenticeship | I10: 6 - Middle Georgia | J10: Chattahoochee Technical College
B11: Metals & Fabrication | C11: Non-credit / Continuing Ed | I11: 7 - Central Savannah River | J11: Coastal Pines Technical College
B12: Hospitals & Health Systems | I12: 8 - River Valley | J12: Columbus Technical College
B13: Allied Health | I13: 9 - Heart of Georgia Altamaha | J13: Georgia Northwestern Technical College
B14: Nursing | I14: 10 - Southwest Georgia | J14: Georgia Piedmont Technical College
B15: Long-Term & Senior Care | I15: 11 - Southern Georgia | J15: Gwinnett Technical College
B16: Behavioral Health | I16: 12 - Coastal Georgia | J16: Lanier Technical College
B17: Pharmaceutical Manufacturing | J17: North Georgia Technical College
B18: Medical Devices | J18: Oconee Fall Line Technical College
B19: Agricultural Biotechnology | J19: Ogeechee Technical College
B20: Animal Health | J20: Savannah Technical College
B21: Clinical Research & Labs | J21: South Georgia Technical College
B22: Corporate Headquarters | J22: Southeastern Technical College
B23: Finance & Insurance | J23: Southern Crescent Technical College
B24: Accounting & Legal | J24: Southern Regional Technical College
B25: Engineering & Design | J25: West Georgia Technical College
B26: Logistics & Supply Chain Management | J26: Wiregrass Georgia Technical College
B27: Software Development | J27: Augusta University
B28: Cybersecurity | J28: Georgia Institute of Technology
... B31: IT Support & Networking | J31: Georgia Southern University
J32: Kennesaw State University
J33: University of West Georgia
J34: Valdosta State University
J35: Albany State University
J36: Clayton State University
J37: Columbus State University
J38: Fort Valley State University
J39: Georgia College & State University
J40: Georgia Southwestern State University
J41: Middle Georgia State University
J42: Savannah State University
J43: University of North Georgia
...

Sheet Sub-sector map
A1: Sub-sector map
A2: Which industry each sub-sector belongs to. Use this when filling the sub-sector columns.
A4: Industry | B4: Sub-sector
A5: Advanced Manufacturing | B5: Automotive & EV
A6: Advanced Manufacturing | B6: Aerospace & Defense
A7: Advanced Manufacturing | B7: Food & Beverage Processing
A8: Advanced Manufacturing | B8: Industrial Machinery
A9: Advanced Manufacturing | B9: Textiles & Flooring
A10: Advanced Manufacturing | B10: Forest Products & Packaging
A11: Advanced Manufacturing | B11: Metals & Fabrication
A12: Healthcare | B12: Hospitals & Health Systems
A13: Healthcare | B13: Allied Health
A14: Healthcare | B14: Nursing
A15: Healthcare | B15: Long-Term & Senior Care
... A31: Technology & IT | B31: IT Support & Networking
