Workbook

Sheet Instructions
A1: Program Curation Template
A2: Statewide Pathway Explorer — technical college and university programs aligned to the five target industries
A4: What this is for
A5: One row per program. The goal is roughly 300-600 programs that genuinely serve the five target industries -- not the full 600+ TCSG catalog. Quality beats coverage.
A7: Start here
A8: Do the four showcase counties first: Forsyth, Jackson, Houston, Ware. Curate every relevant program at Lanier Tech, Athens Tech, Central Georgia Tech, and Coastal Pines before going wider. Finishing four counties end-to-end will expose problems with this template while fixing them is still cheap.
A10: The one column that matters most: CIP code
A11: CIP is the federal Classification of Instructional Programs code. It is what lets the site compute -- rather than guess -- which occupations a program leads to, and therefore which industries and which counties it serves. Every college publishes it in their catalog. A row without a CIP code cannot be aligned automatically and will need manual mapping later, so please do not skip it.
A12: Format: six digits with a period, e.g. 48.0508. Keep it as text so leading zeros survive.
A14: How to fill it in
A15: 1. Work one institution at a time, straight from their online catalog. Do not work from memory.
A16: 2. Yellow rows are worked examples. Delete them before the final import.
... A32: Programs -- the data entry sheet. Progress -- live counts, no editing. Reference / Sub-sector map -- dropdown sources.

Sheet Programs
A1: Ref | B1: Institution | C1: System | D1: Campus | E1: Campus county | F1: Program name | G1: CIP code | H1: Credential type | I1: Length (months) | J1: Delivery mode | K1: Primary industry | L1: Sub-sector | M1: Secondary industry | N1: HOPE Career Grant | O1: Primary SOC | P1: Secondary SOC | Q1: Catalog URL | R1: Short description | S1: Verified date | T1: Verified by | U1: Status | V1: QC check
A2: EX-001 | B2: Lanier Technical College | C2: TCSG | D2: Jackson Campus | E2: Jackson | F2: Industrial Systems Technology | G2: 47.0303 | H2: Associate | I2: 21 | J2: In person | K2: Advanced Manufacturing | L2: Industrial Machinery | N2: Yes | O2: 49-9041 | P2: 49-9043 | Q2: https://www.laniertech.edu/ | R2: Maintains and repairs automated production equipment. | S2: 2026-08-12 | T2: AG | U2: Example | V2: =IF(COUNTA(B2:U2)=0,"",IF(ISBLANK(F2),"Missing program name",IF(ISBLANK(G2),"Missing CIP code",IF(ISBLANK(B2),"Missing institution",IF(ISBLANK(E2),"Missing campus county",IF(ISBLANK(K2),"Missing industry",IF(ISBLANK(H2),"Missing credential type","OK")))))))
A3: EX-002 | B3: Lanier Technical College | C3: TCSG | D3: Forsyth Campus | E3: Forsyth | F3: Computer Programming | G3: 11.0201 | H3: Associate | I3: 18 | J3: Hybrid | K3: Technology & IT | L3: Software Development | N3: Yes | O3: 15-1251 | Q3: https://www.laniertech.edu/ | R3: Application development in current languages and frameworks. | S3: 2026-08-12 | T3: AG | U3: Example | V3: =IF(COUNTA(B3:U3)=0,"",IF(ISBLANK(F3),"Missing program name",IF(ISBLANK(G3),"Missing CIP code",IF(ISBLANK(B3),"Missing institution",IF(ISBLANK(E3),"Missing campus county",IF(ISBLANK(K3),"Missing industry",IF(ISBLANK(H3),"Missing credential type","OK")))))))
A4: EX-003 | B4: Central Georgia Technical College | C4: TCSG | D4: Warner Robins Campus | E4: Houston | F4: Aviation Maintenance Technology | G4: 47.0607 | H4: Diploma | I4: 18 | J4: In person | K4: Advanced Manufacturing | L4: Aerospace & Defense | N4: Yes | O4: 49-3011 | Q4: https://www.centralgatech.edu/ | R4: Airframe and powerplant maintenance; feeds the Robins AFB ecosystem. | S4: 2026-08-12 | T4: AG | U4: Example | V4: =IF(COUNTA(B4:U4)=0,"",IF(ISBLANK(F4),"Missing program name",IF(ISBLANK(G4),"Missing CIP code",IF(ISBLANK(B4),"Missing institution",IF(ISBLANK(E4),"Missing campus county",IF(ISBLANK(K4),"Missing industry",IF(ISBLANK(H4),"Missing credential type","OK")))))))
A5: EX-004 | B5: Coastal Pines Technical College | C5: TCSG | D5: Waycross Campus | E5: Ware | F5: Welding and Joining Technology | G5: 48.0508 | H5: Diploma | I5: 12 | J5: In person | K5: Advanced Manufacturing | L5: Metals & Fabrication | N5: Yes | O5: 51-4121 | Q5: https://coastalpines.edu/ | R5: Structural and pipe welding for manufacturing and rail. | S5: 2026-08-12 | T5: AG | U5: Example | V5: =IF(COUNTA(B5:U5)=0,"",IF(ISBLANK(F5),"Missing program name",IF(ISBLANK(G5),"Missing CIP code",IF(ISBLANK(B5),"Missing institution",IF(ISBLANK(E5),"Missing campus county",IF(ISBLANK(K5),"Missing industry",IF(ISBLANK(H5),"Missing credential type","OK")))))))
A6: EX-005 | B6: Coastal Pines Technical College | C6: TCSG | D6: Waycross Campus | E6: Ware | F6: Practical Nursing | G6: 51.3901 | H6: Diploma | I6: 12 | J6: In person | K6: Healthcare | L6: Nursing | N6: Yes | O6: 29-2061 | Q6: https://coastalpines.edu/ | R6: Prepares students for NCLEX-PN licensure. | S6: 2026-08-12 | T6: AG | U6: Example | V6: =IF(COUNTA(B6:U6)=0,"",IF(ISBLANK(F6),"Missing program name",IF(ISBLANK(G6),"Missing CIP code",IF(ISBLANK(B6),"Missing institution",IF(ISBLANK(E6),"Missing campus county",IF(ISBLANK(K6),"Missing industry",IF(ISBLANK(H6),"Missing credential type","OK")))))))
A7: EX-006 | B7: Middle Georgia State University | C7: USG | D7: Warner Robins Campus | E7: Houston | F7: Information Technology | G7: 11.0103 | H7: Bachelor's | I7: 48 | J7: Hybrid | K7: Technology & IT | L7: Cybersecurity | M7: Professional Services & HQ | N7: No | O7: 15-1212 | P7: 15-1244 | Q7: https://www.mga.edu/ | R7: IT and cyber degree serving the Robins AFB workforce. | S7: 2026-08-12 | T7: AG | U7: Example | V7: =IF(COUNTA(B7:U7)=0,"",IF(ISBLANK(F7),"Missing program name",IF(ISBLANK(G7),"Missing CIP code",IF(ISBLANK(B7),"Missing institution",IF(ISBLANK(E7),"Missing campus county",IF(ISBLANK(K7),"Missing industry",IF(ISBLANK(H7),"Missing credential type","OK")))))))
A8: EX-007 | B8: Athens Technical College | C8: TCSG | D8: Athens Campus | E8: Clarke | F8: Mechatronics | G8: 15.0405 | H8: Technical Certificate of Credit | I8: 9 | J8: In person | K8: Advanced Manufacturing | L8: Automotive & EV | N8: Yes | O8: 17-3024 | Q8: https://www.athenstech.edu/ | R8: Electromechanical systems; feeds EV battery manufacturing. | S8: 2026-08-12 | T8: AG | U8: Example | V8: =IF(COUNTA(B8:U8)=0,"",IF(ISBLANK(F8),"Missing program name",IF(ISBLANK(G8),"Missing CIP code",IF(ISBLANK(B8),"Missing institution",IF(ISBLANK(E8),"Missing campus county",IF(ISBLANK(K8),"Missing industry",IF(ISBLANK(H8),"Missing credential type","OK")))))))
V9: =IF(COUNTA(B9:U9)=0,"",IF(ISBLANK(F9),"Missing program name",IF(ISBLANK(G9),"Missing CIP code",IF(ISBLANK(B9),"Missing institution",IF(ISBLANK(E9),"Missing campus county",IF(ISBLANK(K9),"Missing industry",IF(ISBLANK(H9),"Missing credential type","OK")))))))
V10: =IF(COUNTA(B10:U10)=0,"",IF(ISBLANK(F10),"Missing program name",IF(ISBLANK(G10),"Missing CIP code",IF(ISBLANK(B10),"Missing institution",IF(ISBLANK(E10),"Missing campus county",IF(ISBLANK(K10),"Missing industry",IF(ISBLANK(H10),"Missing credential type","OK")))))))
V11: =IF(COUNTA(B11:U11)=0,"",IF(ISBLANK(F11),"Missing program name",IF(ISBLANK(G11),"Missing CIP code",IF(ISBLANK(B11),"Missing institution",IF(ISBLANK(E11),"Missing campus county",IF(ISBLANK(K11),"Missing industry",IF(ISBLANK(H11),"Missing credential type","OK")))))))
V12: =IF(COUNTA(B12:U12)=0,"",IF(ISBLANK(F12),"Missing program name",IF(ISBLANK(G12),"Missing CIP code",IF(ISBLANK(B12),"Missing institution",IF(ISBLANK(E12),"Missing campus county",IF(ISBLANK(K12),"Missing industry",IF(ISBLANK(H12),"Missing credential type","OK")))))))
V13: =IF(COUNTA(B13:U13)=0,"",IF(ISBLANK(F13),"Missing program name",IF(ISBLANK(G13),"Missing CIP code",IF(ISBLANK(B13),"Missing institution",IF(ISBLANK(E13),"Missing campus county",IF(ISBLANK(K13),"Missing industry",IF(ISBLANK(H13),"Missing credential type","OK")))))))
V14: =IF(COUNTA(B14:U14)=0,"",IF(ISBLANK(F14),"Missing program name",IF(ISBLANK(G14),"Missing CIP code",IF(ISBLANK(B14),"Missing institution",IF(ISBLANK(E14),"Missing campus county",IF(ISBLANK(K14),"Missing industry",IF(ISBLANK(H14),"Missing credential type","OK")))))))
V15: =IF(COUNTA(B15:U15)=0,"",IF(ISBLANK(F15),"Missing program name",IF(ISBLANK(G15),"Missing CIP code",IF(ISBLANK(B15),"Missing institution",IF(ISBLANK(E15),"Missing campus county",IF(ISBLANK(K15),"Missing industry",IF(ISBLANK(H15),"Missing credential type","OK")))))))
V16: =IF(COUNTA(B16:U16)=0,"",IF(ISBLANK(F16),"Missing program name",IF(ISBLANK(G16),"Missing CIP code",IF(ISBLANK(B16),"Missing institution",IF(ISBLANK(E16),"Missing campus county",IF(ISBLANK(K16),"Missing industry",IF(ISBLANK(H16),"Missing credential type","OK")))))))
V17: =IF(COUNTA(B17:U17)=0,"",IF(ISBLANK(F17),"Missing program name",IF(ISBLANK(G17),"Missing CIP code",IF(ISBLANK(B17),"Missing institution",IF(ISBLANK(E17),"Missing campus county",IF(ISBLANK(K17),"Missing industry",IF(ISBLANK(H17),"Missing credential type","OK")))))))
V18: =IF(COUNTA(B18:U18)=0,"",IF(ISBLANK(F18),"Missing program name",IF(ISBLANK(G18),"Missing CIP code",IF(ISBLANK(B18),"Missing institution",IF(ISBLANK(E18),"Missing campus county",IF(ISBLANK(K18),"Missing industry",IF(ISBLANK(H18),"Missing credential type","OK")))))))
V19: =IF(COUNTA(B19:U19)=0,"",IF(ISBLANK(F19),"Missing program name",IF(ISBLANK(G19),"Missing CIP code",IF(ISBLANK(B19),"Missing institution",IF(ISBLANK(E19),"Missing campus county",IF(ISBLANK(K19),"Missing industry",IF(ISBLANK(H19),"Missing credential type","OK")))))))
V20: =IF(COUNTA(B20:U20)=0,"",IF(ISBLANK(F20),"Missing program name",IF(ISBLANK(G20),"Missing CIP code",IF(ISBLANK(B20),"Missing institution",IF(ISBLANK(E20),"Missing campus county",IF(ISBLANK(K20),"Missing industry",IF(ISBLANK(H20),"Missing credential type","OK")))))))
... V401: =IF(COUNTA(B401:U401)=0,"",IF(ISBLANK(F401),"Missing program name",IF(ISBLANK(G401),"Missing CIP code",IF(ISBLANK(B401),"Missing institution",IF(ISBLANK(E401),"Missing campus county",IF(ISBLANK(K401),"Missing industry",IF(ISBLANK(H401),"Missing credential type","OK")))))))

Sheet Progress
A1: Curation progress
A2: All figures calculate from the Programs tab. Nothing here needs editing.
A4: Overall
A5: Programs entered | B5: =COUNTA(Programs!$F$2:$F$401)
A6: Rows passing QC | B6: =COUNTIF(Programs!$V$2:$V$401,"OK")
A7: Rows with a problem | B7: =$B$5-$B$6
A8: Missing a CIP code | B8: =COUNTIF(Programs!$V$2:$V$401,"Missing CIP code")
A9: Ready for import | B9: =COUNTIF(Programs!$U$2:$U$401,"Ready for import")
A10: Target (low end of range) | B10: 300
A11: Percent of target | B11: =IF($B$10=0,0,$B$5/$B$10)
A13: By industry
A14: Advanced Manufacturing | B14: =COUNTIF(Programs!$K$2:$K$401,$A14)
A15: Healthcare | B15: =COUNTIF(Programs!$K$2:$K$401,$A15)
A16: Bio & Life Sciences | B16: =COUNTIF(Programs!$K$2:$K$401,$A16)
A17: Professional Services & HQ | B17: =COUNTIF(Programs!$K$2:$K$401,$A17)
A18: Technology & IT | B18: =COUNTIF(Programs!$K$2:$K$401,$A18)
A20: By showcase county
A21: Forsyth | B21: =COUNTIF(Programs!$E$2:$E$401,$A21)
A22: Jackson | B22: =COUNTIF(Programs!$E$2:$E$401,$A22)
A23: Houston | B23: =COUNTIF(Programs!$E$2:$E$401,$A23)
A24: Ware | B24: =COUNTIF(Programs!$E$2:$E$401,$A24)

Sheet Reference
A1: Reference lists
A2: Dropdown sources. Add rows at the bottom of a list to extend it; do not reorder or delete columns.
A4: Industry | B4: Sub-sector | C4: Credential type | D4: Delivery mode | E4: Yes/No | F4: Status | G4: Confidence | H4: System | I4: Region | J4: Institution
A5: Advanced Manufacturing | B5: Automotive & EV | C5: Technical Certificate of Credit | D5: In person | E5: Yes | F5: Example | G5: High | H5: TCSG | I5: 1 - Northwest Georgia | J5: Albany Technical College
A6: Healthcare | B6: Aerospace & Defense | C6: Diploma | D6: Hybrid | E6: No | F6: Draft | G6: Medium | H6: USG | I6: 2 - Georgia Mountains | J6: Athens Technical College
A7: Bio & Life Sciences | B7: Food & Beverage Processing | C7: Associate | D7: Online | E7: Unknown | F7: Needs review | G7: Low | H7: Private | I7: 3 - Atlanta Regional | J7: Atlanta Technical College
A8: Professional Services & HQ | B8: Industrial Machinery | C8: Bachelor's | F8: Ready for import | H8: Other | I8: 4 - Three Rivers | J8: Augusta Technical College
A9: Technology & IT | B9: Textiles & Flooring | C9: Master's | I9: 5 - Northeast Georgia | J9: Central Georgia Technical College
B10: Forest Products & Packaging | C10: Apprenticeship | I10: 6 - Middle Georgia | J10: Chattahoochee Technical College
B11: Metals & Fabrication | C11: Non-credit / Continuing Ed | I11: 7 - Central Savannah River | J11: Coastal Pines Technical College
B12: Hospitals & Health Systems | I12: 8 - River Valley | J12: Columbus Technical College
B13: Allied Health | I13: 9 - Heart of Georgia Altamaha | J13: Georgia Northwestern Technical College
B14: Nursing | I14: 10 - Southwest Georgia | J14: Georgia Piedmont Technical College
B15: Long-Term & Senior Care | I15: 11 - Southern Georgia | J15: Gwinnett Technical College
B16: Behavioral Health | I16: 12 - Coastal Georgia | J16: Lanier Technical College
B17: Pharmaceutical Manufacturing | J17: North Georgia Technical College
B18: Medical Devices | J18: Oconee Fall Line Technical College
B19: Agricultural Biotechnology | J19: Ogeechee Technical College
B20: Animal Health | J20: Savannah Technical College
B21: Clinical Research & Labs | J21: South Georgia Technical College
B22: Corporate Headquarters | J22: Southeastern Technical College
B23: Finance & Insurance | J23: Southern Crescent Technical College
B24: Accounting & Legal | J24: Southern Regional Technical College
B25: Engineering & Design | J25: West Georgia Technical College
B26: Logistics & Supply Chain Management | J26: Wiregrass Georgia Technical College
B27: Software Development | J27: Augusta University
B28: Cybersecurity | J28: Georgia Institute of Technology
... B31: IT Support & Networking | J31: Georgia Southern University
J32: Kennesaw State University
J33: University of West Georgia
J34: Valdosta State University
J35: Albany State University
J36: Clayton State University
J37: Columbus State University
J38: Fort Valley State University
J39: Georgia College & State University
J40: Georgia Southwestern State University
J41: Middle Georgia State University
J42: Savannah State University
J43: University of North Georgia
...

Sheet Sub-sector map
A1: Sub-sector map
A2: Which industry each sub-sector belongs to. Use this when filling the sub-sector columns.
A4: Industry | B4: Sub-sector
A5: Advanced Manufacturing | B5: Automotive & EV
A6: Advanced Manufacturing | B6: Aerospace & Defense
A7: Advanced Manufacturing | B7: Food & Beverage Processing
A8: Advanced Manufacturing | B8: Industrial Machinery
A9: Advanced Manufacturing | B9: Textiles & Flooring
A10: Advanced Manufacturing | B10: Forest Products & Packaging
A11: Advanced Manufacturing | B11: Metals & Fabrication
A12: Healthcare | B12: Hospitals & Health Systems
A13: Healthcare | B13: Allied Health
A14: Healthcare | B14: Nursing
A15: Healthcare | B15: Long-Term & Senior Care
... A31: Technology & IT | B31: IT Support & Networking
